Workbook

Sheet ÍNDICE
A1: GRUPO MAGNUS — ÍNDICE DE DIAS (JUL—DEZ 2026)
A3: JULHO 2026
A4: 01/07/2026 (Qua) | B4: Ver aba '01_07'
A5: 02/07/2026 (Qui) | B5: Ver aba '02_07'
A6: 03/07/2026 (Sex) | B6: Ver aba '03_07'
A7: 06/07/2026 (Seg) | B7: Ver aba '06_07'
A8: 07/07/2026 (Ter) | B8: Ver aba '07_07'
A9: 08/07/2026 (Qua) | B9: Ver aba '08_07'
A10: 09/07/2026 (Qui) | B10: Ver aba '09_07'
A11: 10/07/2026 (Sex) | B11: Ver aba '10_07'
A12: 13/07/2026 (Seg) | B12: Ver aba '13_07'
A13: 14/07/2026 (Ter) | B13: Ver aba '14_07'
A14: 15/07/2026 (Qua) | B14: Ver aba '15_07'
A15: 16/07/2026 (Qui) | B15: Ver aba '16_07'
... A26: 31/07/2026 (Sex) | B26: Ver aba '31_07'
A28: AGOSTO 2026
A29: 03/08/2026 (Seg) | B29: Ver aba '03_08'
A30: 04/08/2026 (Ter) | B30: Ver aba '04_08'
A31: 05/08/2026 (Qua) | B31: Ver aba '05_08'
A32: 06/08/2026 (Qui) | B32: Ver aba '06_08'
A33: 07/08/2026 (Sex) | B33: Ver aba '07_08'
A34: 10/08/2026 (Seg) | B34: Ver aba '10_08'
A35: 11/08/2026 (Ter) | B35: Ver aba '11_08'
A36: 12/08/2026 (Qua) | B36: Ver aba '12_08'
A37: 13/08/2026 (Qui) | B37: Ver aba '13_08'
A38: 14/08/2026 (Sex) | B38: Ver aba '14_08'
A39: 17/08/2026 (Seg) | B39: Ver aba '17_08'
A40: 18/08/2026 (Ter) | B40: Ver aba '18_08'
... A49: 31/08/2026 (Seg) | B49: Ver aba '31_08'
A51: SETEMBRO 2026
A52: 01/09/2026 (Ter) | B52: Ver aba '01_09'
A53: 02/09/2026 (Qua) | B53: Ver aba '02_09'
A54: 03/09/2026 (Qui) | B54: Ver aba '03_09'
A55: 04/09/2026 (Sex) | B55: Ver aba '04_09'
A56: 07/09/2026 (Seg) | B56: Ver aba '07_09'
A57: 08/09/2026 (Ter) | B57: Ver aba '08_09'
A58: 09/09/2026 (Qua) | B58: Ver aba '09_09'
A59: 10/09/2026 (Qui) | B59: Ver aba '10_09'
A60: 11/09/2026 (Sex) | B60: Ver aba '11_09'
A61: 14/09/2026 (Seg) | B61: Ver aba '14_09'
...

Sheet 01_07
A1: GRUPO MAGNUS · PAINEL DE SALDOS BANCÁRIOS · 01/07/2026
A2: Quarta-feira • Julho/2026 • Dia útil 1 de 132 | F2: Próximo: 02/07 ▶
A4: BANCO / CONTA | B4: SALDO ATUAL | C4: CH. ESP. LIMITE | D4: CH. ESP. USADO | E4: C. GAR. LIMITE | F4: C. GAR. USADA | G4: TOTAL DISPONÍVEL | H4: A PAGAR HOJE | I4: SALDO PÓS-PAG. | J4: DIAS CH. ESPECIAL | K4: SALDO ATUAL + GET NET
A5: ALFENAS
A6: Banco do Brasil | B6: 95.8 | C6: 50000 | G6: =B6+(C6+D6)+(E6+F6) -> 50095.8 | I6: =B6+H6 -> 95.8 | K6: =I6 -> 95.8
A7: Bradesco | B7: 43.71 | C7: 50000 | G7: =B7+(C7+D7)+(E7+F7) -> 50043.71 | I7: =B7+H7 -> 43.71 | K7: =I7 -> 43.71
A8: Santander | C8: 100000 | D8: -14711.17 | E8: 150000 | G8: =B8+(C8+D8)+(E8+F8) -> 235288.83 | H8: -159430.18 | I8: =B8+H8 -> -159430.18 | J8: =IF(D8<0,1,0) -> 1 | K8: =I8 -> -159430.18
A9: CEF | B9: 164.62 | G9: =B9+(C9+D9)+(E9+F9) -> 164.62 | I9: =B9+H9 -> 164.62 | K9: =I9 -> 164.62
A10: Unicred | B10: 51.44 | G10: =B10+(C10+D10)+(E10+F10) -> 51.44 | I10: =B10+H10 -> 51.44 | K10: =I10 -> 51.44
A11: Get Net | B11: 247845.01 | C11: ← Saldo disponível para antecipação de recebíveis | K11: =B11 -> 247845.01
A12: SALDO DISPONÍVEL | B12: =SUM(B6:B10) -> 355.57 | C12: =C6+C7+C8+C9+C10 -> 200000 | D12: =D6+D7+D8+D9+D10 -> -14711.17 | E12: =E6+E7+E8+E9+E10 -> 150000 | F12: =F6+F7+F8+F9+F10 -> 0 | G12: =G6+G7+G8+G9+G10 -> 335644.4 | H12: =H6+H7+H8+H9+H10 -> -159430.18 | I12: =I6+I7+I8+I9+I10 -> -159074.61 | J12: =J8 -> 1 | K12: =B12+B11 -> 248200.58
A13: 📥 Empréstimo Mútuo — Adquirido (valor devido a outra unidade)
A14: 📤 Empréstimo Mútuo — Emprestado (valor a receber de outra unidade)
A15: POSIÇÃO LÍQUIDA = Saldo Atual + Get Net + Ch.Esp + C.Gar − Emp. Adquirido + Emp. Emprestado | K15: =K12+D12+F12-IF(ISNUMBER(K13),K13,0)+IF(ISNUMBER(K14),K14,0) -> 233489.41
A17: CAMPINAS
A18: Santander | B18: 22549.03 | C18: 160000 | G18: =B18+(C18+D18)+(E18+F18) -> 182549.03 | H18: -74808.45 | I18: =B18+H18 -> -52259.42 | J18: =IF(D18<0,1,0) -> 0 | K18: =I18 -> -52259.42
A19: Unicred PJ | E19: 200000 | F19: -198414.01 | G19: =B19+(C19+D19)+(E19+F19) -> 1585.99 | I19: =B19+H19 -> 0 | K19: =I19 -> 0
A20: Unicred PF | B20: 54898.3 | G20: =B20+(C20+D20)+(E20+F20) -> 54898.3 | I20: =B20+H20 -> 54898.3 | K20: =I20 -> 54898.3
A21: Bradesco | B21: 121.27 | G21: =B21+(C21+D21)+(E21+F21) -> 121.27 | I21: =B21+H21 -> 121.27 | K21: =I21 -> 121.27
A22: Get Net | B22: 100862.61 | C22: ← Saldo disponível para antecipação de recebíveis | K22: =B22 -> 100862.61
A23: SALDO DISPONÍVEL | B23: =SUM(B18:B21) -> 77568.6 | C23: =C18+C19+C20+C21 -> 160000 | D23: =D18+D19+D20+D21 -> 0 | E23: =E18+E19+E20+E21 -> 200000 | F23: =F18+F19+F20+F21 -> -198414.01 | G23: =G18+G19+G20+G21 -> 239154.59 | H23: =H18+H19+H20+H21 -> -74808.45 | I23: =I18+I19+I20+I21 -> 2760.15 | J23: =J18 -> 0 | K23: =B23+B22 -> 178431.21
A24: 📥 Empréstimo Mútuo — Adquirido (valor devido a outra unidade)
A25: 📤 Empréstimo Mútuo — Emprestado (valor a receber de outra unidade)
A26: POSIÇÃO LÍQUIDA = Saldo Atual + Get Net + Ch.Esp + C.Gar − Emp. Adquirido + Emp. Emprestado | K26: =K23+D23+F23-IF(ISNUMBER(K24),K24,0)+IF(ISNUMBER(K25),K25,0) -> -19982.8
A28: VARGINHA
A29: Santander | B29: 56567.75 | C29: 100000 | E29: 50000 | G29: =B29+(C29+D29)+(E29+F29) -> 206567.75 | H29: -96219.41 | I29: =B29+H29 -> -39651.66 | J29: =IF(D29<0,1,0) -> 0 | K29: =I29 -> -39651.66
A30: Unicred | B30: 52.68 | C30: 50000 | G30: =B30+(C30+D30)+(E30+F30) -> 50052.68 | I30: =B30+H30 -> 52.68 | K30: =I30 -> 52.68
A31: Bradesco | B31: 22.43 | G31: =B31+(C31+D31)+(E31+F31) -> 22.43 | I31: =B31+H31 -> 22.43 | K31: =I31 -> 22.43
A32: Itaú CC | G32: =B32+(C32+D32)+(E32+F32) -> 0 | I32: =B32+H32 -> 0 | K32: =I32 -> 0
A33: Eireli | B33: 21795.96 | G33: =B33+(C33+D33)+(E33+F33) -> 21795.96 | I33: =B33+H33 -> 21795.96 | K33: =I33 -> 21795.96
A34: Get Net | B34: 290630.8 | C34: ← Saldo disponível para antecipação de recebíveis | K34: =B34 -> 290630.8
A35: SALDO DISPONÍVEL | B35: =SUM(B29:B33) -> 78438.82 | C35: =C29+C30+C31+C32+C33 -> 150000 | D35: =D29+D30+D31+D32+D33 -> 0 | E35: =E29+E30+E31+E32+E33 -> 50000 | F35: =F29+F30+F31+F32+F33 -> 0 | G35: =G29+G30+G31+G32+G33 -> 278438.82 | H35: =H29+H30+H31+H32+H33 -> -96219.41 | I35: =I29+I30+I31+I32+I33 -> -17780.59 | J35: =J29 -> 0 | K35: =B35+B34 -> 369069.62
A36: 📥 Empréstimo Mútuo — Adquirido (valor devido a outra unidade)
A37: 📤 Empréstimo Mútuo — Emprestado (valor a receber de outra unidade)
A38: POSIÇÃO LÍQUIDA = Saldo Atual + Get Net + Ch.Esp + C.Gar − Emp. Adquirido + Emp. Emprestado | K38: =K35+D35+F35-IF(ISNUMBER(K36),K36,0)+IF(ISNUMBER(K37),K37,0) -> 369069.62
A40: ITAJUBÁ
A41: Santander | B41: 48802.53 | C41: 78000 | E41: 100000 | F41: -60000 | G41: =B41+(C41+D41)+(E41+F41) -> 166802.53 | H41: -95780.36 | I41: =B41+H41 -> -46977.83 | J41: =IF(D41<0,1,0) -> 0 | K41: =I41 -> -46977.83
A42: Itaú CC | G42: =B42+(C42+D42)+(E42+F42) -> 0 | I42: =B42+H42 -> 0 | K42: =I42 -> 0
A43: Itatesla | B43: 76.23 | G43: =B43+(C43+D43)+(E43+F43) -> 76.23 | I43: =B43+H43 -> 76.23 | K43: =I43 -> 76.23
A44: Get Net | C44: ← Saldo disponível para antecipação de recebíveis | K44: =B44 -> 0
...

Sheet 02_07
A1: GRUPO MAGNUS · PAINEL DE SALDOS BANCÁRIOS · 02/07/2026
A2: Quinta-feira • Julho/2026 • Dia útil 2 de 132 | F2: ◀ 01/07 Próximo: 03/07 ▶
A4: BANCO / CONTA | B4: SALDO ATUAL | C4: CH. ESP. LIMITE | D4: CH. ESP. USADO | E4: C. GAR. LIMITE | F4: C. GAR. USADA | G4: TOTAL DISPONÍVEL | H4: A PAGAR HOJE | I4: SALDO PÓS-PAG. | J4: DIAS CH. ESPECIAL | K4: SALDO ATUAL + GET NET
A5: ALFENAS
A6: Banco do Brasil | B6: 95.8 | C6: 50000 | G6: =B6+(C6+D6)+(E6+F6) -> 50095.8 | I6: =B6+H6 -> 95.8 | K6: =I6 -> 95.8
A7: Bradesco | B7: 43.71 | C7: 50000 | G7: =B7+(C7+D7)+(E7+F7) -> 50043.71 | I7: =B7+H7 -> 43.71 | K7: =I7 -> 43.71
A8: Santander | C8: 100000 | D8: -14711.17 | E8: 150000 | G8: =B8+(C8+D8)+(E8+F8) -> 235288.83 | H8: -159430.18 | I8: =B8+H8 -> -159430.18 | J8: =IF(D8<0,1+IF('01_07'!D8<0,'01_07'!J8,0),0) -> 2 | K8: =I8 -> -159430.18
A9: CEF | B9: 164.62 | G9: =B9+(C9+D9)+(E9+F9) -> 164.62 | I9: =B9+H9 -> 164.62 | K9: =I9 -> 164.62
A10: Unicred | B10: 51.44 | G10: =B10+(C10+D10)+(E10+F10) -> 51.44 | I10: =B10+H10 -> 51.44 | K10: =I10 -> 51.44
A11: Get Net | B11: 247845.01 | C11: ← Saldo disponível para antecipação de recebíveis | K11: =B11 -> 247845.01
A12: SALDO DISPONÍVEL | B12: =SUM('01_07'!I6:I10) -> -159074.61 | C12: =C6+C7+C8+C9+C10 -> 200000 | D12: =D6+D7+D8+D9+D10 -> -14711.17 | E12: =E6+E7+E8+E9+E10 -> 150000 | F12: =F6+F7+F8+F9+F10 -> 0 | G12: =G6+G7+G8+G9+G10 -> 335644.4 | H12: =H6+H7+H8+H9+H10 -> -159430.18 | I12: =I6+I7+I8+I9+I10 -> -159074.61 | J12: =J8 -> 2 | K12: =B12+B11 -> 88770.4
A13: 📥 Empréstimo Mútuo — Adquirido (valor devido a outra unidade)
A14: 📤 Empréstimo Mútuo — Emprestado (valor a receber de outra unidade)
A15: POSIÇÃO LÍQUIDA = Saldo Atual + Get Net + Ch.Esp + C.Gar − Emp. Adquirido + Emp. Emprestado | K15: =K12+D12+F12-IF(ISNUMBER(K13),K13,0)+IF(ISNUMBER(K14),K14,0) -> 74059.23
A17: CAMPINAS
A18: Santander | B18: 22549.03 | C18: 160000 | G18: =B18+(C18+D18)+(E18+F18) -> 182549.03 | H18: -74808.45 | I18: =B18+H18 -> -52259.42 | J18: =IF(D18<0,1+IF('01_07'!D18<0,'01_07'!J18,0),0) -> 0 | K18: =I18 -> -52259.42
A19: Unicred PJ | E19: 200000 | F19: -198414.01 | G19: =B19+(C19+D19)+(E19+F19) -> 1585.99 | I19: =B19+H19 -> 0 | K19: =I19 -> 0
A20: Unicred PF | B20: 54898.3 | G20: =B20+(C20+D20)+(E20+F20) -> 54898.3 | I20: =B20+H20 -> 54898.3 | K20: =I20 -> 54898.3
A21: Bradesco | B21: 121.27 | G21: =B21+(C21+D21)+(E21+F21) -> 121.27 | I21: =B21+H21 -> 121.27 | K21: =I21 -> 121.27
A22: Get Net | B22: 100862.61 | C22: ← Saldo disponível para antecipação de recebíveis | K22: =B22 -> 100862.61
A23: SALDO DISPONÍVEL | B23: =SUM('01_07'!I18:I21) -> 2760.15 | C23: =C18+C19+C20+C21 -> 160000 | D23: =D18+D19+D20+D21 -> 0 | E23: =E18+E19+E20+E21 -> 200000 | F23: =F18+F19+F20+F21 -> -198414.01 | G23: =G18+G19+G20+G21 -> 239154.59 | H23: =H18+H19+H20+H21 -> -74808.45 | I23: =I18+I19+I20+I21 -> 2760.15 | J23: =J18 -> 0 | K23: =B23+B22 -> 103622.76
A24: 📥 Empréstimo Mútuo — Adquirido (valor devido a outra unidade)
A25: 📤 Empréstimo Mútuo — Emprestado (valor a receber de outra unidade)
A26: POSIÇÃO LÍQUIDA = Saldo Atual + Get Net + Ch.Esp + C.Gar − Emp. Adquirido + Emp. Emprestado | K26: =K23+D23+F23-IF(ISNUMBER(K24),K24,0)+IF(ISNUMBER(K25),K25,0) -> -94791.25
A28: VARGINHA
A29: Santander | B29: 56567.75 | C29: 100000 | E29: 50000 | G29: =B29+(C29+D29)+(E29+F29) -> 206567.75 | H29: -96219.41 | I29: =B29+H29 -> -39651.66 | J29: =IF(D29<0,1+IF('01_07'!D29<0,'01_07'!J29,0),0) -> 0 | K29: =I29 -> -39651.66
A30: Unicred | B30: 52.68 | C30: 50000 | G30: =B30+(C30+D30)+(E30+F30) -> 50052.68 | I30: =B30+H30 -> 52.68 | K30: =I30 -> 52.68
A31: Bradesco | B31: 22.43 | G31: =B31+(C31+D31)+(E31+F31) -> 22.43 | I31: =B31+H31 -> 22.43 | K31: =I31 -> 22.43
A32: Itaú CC | G32: =B32+(C32+D32)+(E32+F32) -> 0 | I32: =B32+H32 -> 0 | K32: =I32 -> 0
A33: Eireli | B33: 21795.96 | G33: =B33+(C33+D33)+(E33+F33) -> 21795.96 | I33: =B33+H33 -> 21795.96 | K33: =I33 -> 21795.96
A34: Get Net | B34: 290630.8 | C34: ← Saldo disponível para antecipação de recebíveis | K34: =B34 -> 290630.8
A35: SALDO DISPONÍVEL | B35: =SUM('01_07'!I29:I33) -> -17780.59 | C35: =C29+C30+C31+C32+C33 -> 150000 | D35: =D29+D30+D31+D32+D33 -> 0 | E35: =E29+E30+E31+E32+E33 -> 50000 | F35: =F29+F30+F31+F32+F33 -> 0 | G35: =G29+G30+G31+G32+G33 -> 278438.82 | H35: =H29+H30+H31+H32+H33 -> -96219.41 | I35: =I29+I30+I31+I32+I33 -> -17780.59 | J35: =J29 -> 0 | K35: =B35+B34 -> 272850.21
A36: 📥 Empréstimo Mútuo — Adquirido (valor devido a outra unidade)
A37: 📤 Empréstimo Mútuo — Emprestado (valor a receber de outra unidade)
A38: POSIÇÃO LÍQUIDA = Saldo Atual + Get Net + Ch.Esp + C.Gar − Emp. Adquirido + Emp. Emprestado | K38: =K35+D35+F35-IF(ISNUMBER(K36),K36,0)+IF(ISNUMBER(K37),K37,0) -> 272850.21
A40: ITAJUBÁ
A41: Santander | B41: 48802.53 | C41: 78000 | E41: 100000 | F41: -60000 | G41: =B41+(C41+D41)+(E41+F41) -> 166802.53 | H41: -95780.36 | I41: =B41+H41 -> -46977.83 | J41: =IF(D41<0,1+IF('01_07'!D41<0,'01_07'!J41,0),0) -> 0 | K41: =I41 -> -46977.83
A42: Itaú CC | G42: =B42+(C42+D42)+(E42+F42) -> 0 | I42: =B42+H42 -> 0 | K42: =I42 -> 0
A43: Itatesla | B43: 76.23 | G43: =B43+(C43+D43)+(E43+F43) -> 76.23 | I43: =B43+H43 -> 76.23 | K43: =I43 -> 76.23
A44: Get Net | C44: ← Saldo disponível para antecipação de recebíveis | K44: =B44 -> 0
...

Sheet 03_07
A1: GRUPO MAGNUS · PAINEL DE SALDOS BANCÁRIOS · 03/07/2026
A2: Sexta-feira • Julho/2026 • Dia útil 3 de 132 | F2: ◀ 02/07 Próximo: 06/07 ▶
A4: BANCO / CONTA | B4: SALDO ATUAL | C4: CH. ESP. LIMITE | D4: CH. ESP. USADO | E4: C. GAR. LIMITE | F4: C. GAR. USADA | G4: TOTAL DISPONÍVEL | H4: A PAGAR HOJE | I4: SALDO PÓS-PAG. | J4: DIAS CH. ESPECIAL | K4: SALDO ATUAL + GET NET
A5: ALFENAS
A6: Banco do Brasil | B6: 95.8 | C6: 50000 | G6: =B6+(C6+D6)+(E6+F6) -> 50095.8 | I6: =B6+H6 -> 95.8 | K6: =I6 -> 95.8
A7: Bradesco | B7: 43.71 | C7: 50000 | G7: =B7+(C7+D7)+(E7+F7) -> 50043.71 | I7: =B7+H7 -> 43.71 | K7: =I7 -> 43.71
A8: Santander | C8: 100000 | D8: -14711.17 | E8: 150000 | G8: =B8+(C8+D8)+(E8+F8) -> 235288.83 | H8: -159430.18 | I8: =B8+H8 -> -159430.18 | J8: =IF(D8<0,1+IF('02_07'!D8<0,'02_07'!J8,0),0) -> 3 | K8: =I8 -> -159430.18
A9: CEF | B9: 164.62 | G9: =B9+(C9+D9)+(E9+F9) -> 164.62 | I9: =B9+H9 -> 164.62 | K9: =I9 -> 164.62
A10: Unicred | B10: 51.44 | G10: =B10+(C10+D10)+(E10+F10) -> 51.44 | I10: =B10+H10 -> 51.44 | K10: =I10 -> 51.44
A11: Get Net | B11: 247845.01 | C11: ← Saldo disponível para antecipação de recebíveis | K11: =B11 -> 247845.01
A12: SALDO DISPONÍVEL | B12: =SUM('02_07'!I6:I10) -> -159074.61 | C12: =C6+C7+C8+C9+C10 -> 200000 | D12: =D6+D7+D8+D9+D10 -> -14711.17 | E12: =E6+E7+E8+E9+E10 -> 150000 | F12: =F6+F7+F8+F9+F10 -> 0 | G12: =G6+G7+G8+G9+G10 -> 335644.4 | H12: =H6+H7+H8+H9+H10 -> -159430.18 | I12: =I6+I7+I8+I9+I10 -> -159074.61 | J12: =J8 -> 3 | K12: =B12+B11 -> 88770.4
A13: 📥 Empréstimo Mútuo — Adquirido (valor devido a outra unidade)
A14: 📤 Empréstimo Mútuo — Emprestado (valor a receber de outra unidade)
A15: POSIÇÃO LÍQUIDA = Saldo Atual + Get Net + Ch.Esp + C.Gar − Emp. Adquirido + Emp. Emprestado | K15: =K12+D12+F12-IF(ISNUMBER(K13),K13,0)+IF(ISNUMBER(K14),K14,0) -> 74059.23
A17: CAMPINAS
A18: Santander | B18: 22549.03 | C18: 160000 | G18: =B18+(C18+D18)+(E18+F18) -> 182549.03 | H18: -74808.45 | I18: =B18+H18 -> -52259.42 | J18: =IF(D18<0,1+IF('02_07'!D18<0,'02_07'!J18,0),0) -> 0 | K18: =I18 -> -52259.42
A19: Unicred PJ | E19: 200000 | F19: -198414.01 | G19: =B19+(C19+D19)+(E19+F19) -> 1585.99 | I19: =B19+H19 -> 0 | K19: =I19 -> 0
A20: Unicred PF | B20: 54898.3 | G20: =B20+(C20+D20)+(E20+F20) -> 54898.3 | I20: =B20+H20 -> 54898.3 | K20: =I20 -> 54898.3
A21: Bradesco | B21: 121.27 | G21: =B21+(C21+D21)+(E21+F21) -> 121.27 | I21: =B21+H21 -> 121.27 | K21: =I21 -> 121.27
A22: Get Net | B22: 100862.61 | C22: ← Saldo disponível para antecipação de recebíveis | K22: =B22 -> 100862.61
A23: SALDO DISPONÍVEL | B23: =SUM('02_07'!I18:I21) -> 2760.15 | C23: =C18+C19+C20+C21 -> 160000 | D23: =D18+D19+D20+D21 -> 0 | E23: =E18+E19+E20+E21 -> 200000 | F23: =F18+F19+F20+F21 -> -198414.01 | G23: =G18+G19+G20+G21 -> 239154.59 | H23: =H18+H19+H20+H21 -> -74808.45 | I23: =I18+I19+I20+I21 -> 2760.15 | J23: =J18 -> 0 | K23: =B23+B22 -> 103622.76
A24: 📥 Empréstimo Mútuo — Adquirido (valor devido a outra unidade)
A25: 📤 Empréstimo Mútuo — Emprestado (valor a receber de outra unidade)
A26: POSIÇÃO LÍQUIDA = Saldo Atual + Get Net + Ch.Esp + C.Gar − Emp. Adquirido + Emp. Emprestado | K26: =K23+D23+F23-IF(ISNUMBER(K24),K24,0)+IF(ISNUMBER(K25),K25,0) -> -94791.25
A28: VARGINHA
A29: Santander | B29: 56567.75 | C29: 100000 | E29: 50000 | G29: =B29+(C29+D29)+(E29+F29) -> 206567.75 | H29: -96219.41 | I29: =B29+H29 -> -39651.66 | J29: =IF(D29<0,1+IF('02_07'!D29<0,'02_07'!J29,0),0) -> 0 | K29: =I29 -> -39651.66
A30: Unicred | B30: 52.68 | C30: 50000 | G30: =B30+(C30+D30)+(E30+F30) -> 50052.68 | I30: =B30+H30 -> 52.68 | K30: =I30 -> 52.68
A31: Bradesco | B31: 22.43 | G31: =B31+(C31+D31)+(E31+F31) -> 22.43 | I31: =B31+H31 -> 22.43 | K31: =I31 -> 22.43
A32: Itaú CC | G32: =B32+(C32+D32)+(E32+F32) -> 0 | I32: =B32+H32 -> 0 | K32: =I32 -> 0
A33: Eireli | B33: 21795.96 | G33: =B33+(C33+D33)+(E33+F33) -> 21795.96 | I33: =B33+H33 -> 21795.96 | K33: =I33 -> 21795.96
A34: Get Net | B34: 290630.8 | C34: ← Saldo disponível para antecipação de recebíveis | K34: =B34 -> 290630.8
A35: SALDO DISPONÍVEL | B35: =SUM('02_07'!I29:I33) -> -17780.59 | C35: =C29+C30+C31+C32+C33 -> 150000 | D35: =D29+D30+D31+D32+D33 -> 0 | E35: =E29+E30+E31+E32+E33 -> 50000 | F35: =F29+F30+F31+F32+F33 -> 0 | G35: =G29+G30+G31+G32+G33 -> 278438.82 | H35: =H29+H30+H31+H32+H33 -> -96219.41 | I35: =I29+I30+I31+I32+I33 -> -17780.59 | J35: =J29 -> 0 | K35: =B35+B34 -> 272850.21
A36: 📥 Empréstimo Mútuo — Adquirido (valor devido a outra unidade)
A37: 📤 Empréstimo Mútuo — Emprestado (valor a receber de outra unidade)
A38: POSIÇÃO LÍQUIDA = Saldo Atual + Get Net + Ch.Esp + C.Gar − Emp. Adquirido + Emp. Emprestado | K38: =K35+D35+F35-IF(ISNUMBER(K36),K36,0)+IF(ISNUMBER(K37),K37,0) -> 272850.21
A40: ITAJUBÁ
A41: Santander | B41: 48802.53 | C41: 78000 | E41: 100000 | F41: -60000 | G41: =B41+(C41+D41)+(E41+F41) -> 166802.53 | H41: -95780.36 | I41: =B41+H41 -> -46977.83 | J41: =IF(D41<0,1+IF('02_07'!D41<0,'02_07'!J41,0),0) -> 0 | K41: =I41 -> -46977.83
A42: Itaú CC | G42: =B42+(C42+D42)+(E42+F42) -> 0 | I42: =B42+H42 -> 0 | K42: =I42 -> 0
A43: Itatesla | B43: 76.23 | G43: =B43+(C43+D43)+(E43+F43) -> 76.23 | I43: =B43+H43 -> 76.23 | K43: =I43 -> 76.23
A44: Get Net | C44: ← Saldo disponível para antecipação de recebíveis | K44: =B44 -> 0
...

Sheet 06_07
A1: GRUPO MAGNUS · PAINEL DE SALDOS BANCÁRIOS · 06/07/2026
A2: Segunda-feira • Julho/2026 • Dia útil 4 de 132 | F2: ◀ 03/07 Próximo: 07/07 ▶
A4: BANCO / CONTA | B4: SALDO ATUAL | C4: CH. ESP. LIMITE | D4: CH. ESP. USADO | E4: C. GAR. LIMITE | F4: C. GAR. USADA | G4: TOTAL DISPONÍVEL | H4: A PAGAR HOJE | I4: SALDO PÓS-PAG. | J4: DIAS CH. ESPECIAL | K4: SALDO ATUAL + GET NET
A5: ALFENAS
A6: Banco do Brasil | B6: 95.8 | C6: 50000 | G6: =B6+(C6+D6)+(E6+F6) -> 50095.8 | I6: =B6+H6 -> 95.8 | K6: =I6 -> 95.8
A7: Bradesco | B7: 43.71 | C7: 50000 | G7: =B7+(C7+D7)+(E7+F7) -> 50043.71 | I7: =B7+H7 -> 43.71 | K7: =I7 -> 43.71
A8: Santander | C8: 100000 | D8: -14711.17 | E8: 150000 | G8: =B8+(C8+D8)+(E8+F8) -> 235288.83 | H8: -159430.18 | I8: =B8+H8 -> -159430.18 | J8: =IF(D8<0,1+IF('03_07'!D8<0,'03_07'!J8,0),0) -> 4 | K8: =I8 -> -159430.18
A9: CEF | B9: 164.62 | G9: =B9+(C9+D9)+(E9+F9) -> 164.62 | I9: =B9+H9 -> 164.62 | K9: =I9 -> 164.62
A10: Unicred | B10: 51.44 | G10: =B10+(C10+D10)+(E10+F10) -> 51.44 | I10: =B10+H10 -> 51.44 | K10: =I10 -> 51.44
A11: Get Net | B11: 247845.01 | C11: ← Saldo disponível para antecipação de recebíveis | K11: =B11 -> 247845.01
A12: SALDO DISPONÍVEL | B12: =SUM('03_07'!I6:I10) -> -159074.61 | C12: =C6+C7+C8+C9+C10 -> 200000 | D12: =D6+D7+D8+D9+D10 -> -14711.17 | E12: =E6+E7+E8+E9+E10 -> 150000 | F12: =F6+F7+F8+F9+F10 -> 0 | G12: =G6+G7+G8+G9+G10 -> 335644.4 | H12: =H6+H7+H8+H9+H10 -> -159430.18 | I12: =I6+I7+I8+I9+I10 -> -159074.61 | J12: =J8 -> 4 | K12: =B12+B11 -> 88770.4
A13: 📥 Empréstimo Mútuo — Adquirido (valor devido a outra unidade)
A14: 📤 Empréstimo Mútuo — Emprestado (valor a receber de outra unidade)
A15: POSIÇÃO LÍQUIDA = Saldo Atual + Get Net + Ch.Esp + C.Gar − Emp. Adquirido + Emp. Emprestado | K15: =K12+D12+F12-IF(ISNUMBER(K13),K13,0)+IF(ISNUMBER(K14),K14,0) -> 74059.23
A17: CAMPINAS
A18: Santander | B18: 22549.03 | C18: 160000 | G18: =B18+(C18+D18)+(E18+F18) -> 182549.03 | H18: -74808.45 | I18: =B18+H18 -> -52259.42 | J18: =IF(D18<0,1+IF('03_07'!D18<0,'03_07'!J18,0),0) -> 0 | K18: =I18 -> -52259.42
A19: Unicred PJ | E19: 200000 | F19: -198414.01 | G19: =B19+(C19+D19)+(E19+F19) -> 1585.99 | I19: =B19+H19 -> 0 | K19: =I19 -> 0
A20: Unicred PF | B20: 54898.3 | G20: =B20+(C20+D20)+(E20+F20) -> 54898.3 | I20: =B20+H20 -> 54898.3 | K20: =I20 -> 54898.3
A21: Bradesco | B21: 121.27 | G21: =B21+(C21+D21)+(E21+F21) -> 121.27 | I21: =B21+H21 -> 121.27 | K21: =I21 -> 121.27
A22: Get Net | B22: 100862.61 | C22: ← Saldo disponível para antecipação de recebíveis | K22: =B22 -> 100862.61
A23: SALDO DISPONÍVEL | B23: =SUM('03_07'!I18:I21) -> 2760.15 | C23: =C18+C19+C20+C21 -> 160000 | D23: =D18+D19+D20+D21 -> 0 | E23: =E18+E19+E20+E21 -> 200000 | F23: =F18+F19+F20+F21 -> -198414.01 | G23: =G18+G19+G20+G21 -> 239154.59 | H23: =H18+H19+H20+H21 -> -74808.45 | I23: =I18+I19+I20+I21 -> 2760.15 | J23: =J18 -> 0 | K23: =B23+B22 -> 103622.76
A24: 📥 Empréstimo Mútuo — Adquirido (valor devido a outra unidade)
A25: 📤 Empréstimo Mútuo — Emprestado (valor a receber de outra unidade)
A26: POSIÇÃO LÍQUIDA = Saldo Atual + Get Net + Ch.Esp + C.Gar − Emp. Adquirido + Emp. Emprestado | K26: =K23+D23+F23-IF(ISNUMBER(K24),K24,0)+IF(ISNUMBER(K25),K25,0) -> -94791.25
A28: VARGINHA
A29: Santander | B29: 56567.75 | C29: 100000 | E29: 50000 | G29: =B29+(C29+D29)+(E29+F29) -> 206567.75 | H29: -96219.41 | I29: =B29+H29 -> -39651.66 | J29: =IF(D29<0,1+IF('03_07'!D29<0,'03_07'!J29,0),0) -> 0 | K29: =I29 -> -39651.66
A30: Unicred | B30: 52.68 | C30: 50000 | G30: =B30+(C30+D30)+(E30+F30) -> 50052.68 | I30: =B30+H30 -> 52.68 | K30: =I30 -> 52.68
A31: Bradesco | B31: 22.43 | G31: =B31+(C31+D31)+(E31+F31) -> 22.43 | I31: =B31+H31 -> 22.43 | K31: =I31 -> 22.43
A32: Itaú CC | G32: =B32+(C32+D32)+(E32+F32) -> 0 | I32: =B32+H32 -> 0 | K32: =I32 -> 0
A33: Eireli | B33: 21795.96 | G33: =B33+(C33+D33)+(E33+F33) -> 21795.96 | I33: =B33+H33 -> 21795.96 | K33: =I33 -> 21795.96
A34: Get Net | B34: 290630.8 | C34: ← Saldo disponível para antecipação de recebíveis | K34: =B34 -> 290630.8
A35: SALDO DISPONÍVEL | B35: =SUM('03_07'!I29:I33) -> -17780.59 | C35: =C29+C30+C31+C32+C33 -> 150000 | D35: =D29+D30+D31+D32+D33 -> 0 | E35: =E29+E30+E31+E32+E33 -> 50000 | F35: =F29+F30+F31+F32+F33 -> 0 | G35: =G29+G30+G31+G32+G33 -> 278438.82 | H35: =H29+H30+H31+H32+H33 -> -96219.41 | I35: =I29+I30+I31+I32+I33 -> -17780.59 | J35: =J29 -> 0 | K35: =B35+B34 -> 272850.21
A36: 📥 Empréstimo Mútuo — Adquirido (valor devido a outra unidade)
A37: 📤 Empréstimo Mútuo — Emprestado (valor a receber de outra unidade)
A38: POSIÇÃO LÍQUIDA = Saldo Atual + Get Net + Ch.Esp + C.Gar − Emp. Adquirido + Emp. Emprestado | K38: =K35+D35+F35-IF(ISNUMBER(K36),K36,0)+IF(ISNUMBER(K37),K37,0) -> 272850.21
A40: ITAJUBÁ
A41: Santander | B41: 48802.53 | C41: 78000 | E41: 100000 | F41: -60000 | G41: =B41+(C41+D41)+(E41+F41) -> 166802.53 | H41: -95780.36 | I41: =B41+H41 -> -46977.83 | J41: =IF(D41<0,1+IF('03_07'!D41<0,'03_07'!J41,0),0) -> 0 | K41: =I41 -> -46977.83
A42: Itaú CC | G42: =B42+(C42+D42)+(E42+F42) -> 0 | I42: =B42+H42 -> 0 | K42: =I42 -> 0
A43: Itatesla | B43: 76.23 | G43: =B43+(C43+D43)+(E43+F43) -> 76.23 | I43: =B43+H43 -> 76.23 | K43: =I43 -> 76.23
A44: Get Net | C44: ← Saldo disponível para antecipação de recebíveis | K44: =B44 -> 0
...

Sheet 07_07
A1: GRUPO MAGNUS · PAINEL DE SALDOS BANCÁRIOS · 07/07/2026
A2: Terça-feira • Julho/2026 • Dia útil 5 de 132 | F2: ◀ 06/07 Próximo: 08/07 ▶
A4: BANCO / CONTA | B4: SALDO ATUAL | C4: CH. ESP. LIMITE | D4: CH. ESP. USADO | E4: C. GAR. LIMITE | F4: C. GAR. USADA | G4: TOTAL DISPONÍVEL | H4: A PAGAR HOJE | I4: SALDO PÓS-PAG. | J4: DIAS CH. ESPECIAL | K4: SALDO ATUAL + GET NET
A5: ALFENAS
A6: Banco do Brasil | B6: 95.8 | C6: 50000 | G6: =B6+(C6+D6)+(E6+F6) -> 50095.8 | I6: =B6+H6 -> 95.8 | K6: =I6 -> 95.8
A7: Bradesco | B7: 43.71 | C7: 50000 | G7: =B7+(C7+D7)+(E7+F7) -> 50043.71 | I7: =B7+H7 -> 43.71 | K7: =I7 -> 43.71
A8: Santander | C8: 100000 | D8: -14711.17 | E8: 150000 | G8: =B8+(C8+D8)+(E8+F8) -> 235288.83 | H8: -159430.18 | I8: =B8+H8 -> -159430.18 | J8: =IF(D8<0,1+IF('06_07'!D8<0,'06_07'!J8,0),0) -> 5 | K8: =I8 -> -159430.18
A9: CEF | B9: 164.62 | G9: =B9+(C9+D9)+(E9+F9) -> 164.62 | I9: =B9+H9 -> 164.62 | K9: =I9 -> 164.62
A10: Unicred | B10: 51.44 | G10: =B10+(C10+D10)+(E10+F10) -> 51.44 | I10: =B10+H10 -> 51.44 | K10: =I10 -> 51.44
A11: Get Net | B11: 247845.01 | C11: ← Saldo disponível para antecipação de recebíveis | K11: =B11 -> 247845.01
A12: SALDO DISPONÍVEL | B12: =SUM('06_07'!I6:I10) -> -159074.61 | C12: =C6+C7+C8+C9+C10 -> 200000 | D12: =D6+D7+D8+D9+D10 -> -14711.17 | E12: =E6+E7+E8+E9+E10 -> 150000 | F12: =F6+F7+F8+F9+F10 -> 0 | G12: =G6+G7+G8+G9+G10 -> 335644.4 | H12: =H6+H7+H8+H9+H10 -> -159430.18 | I12: =I6+I7+I8+I9+I10 -> -159074.61 | J12: =J8 -> 5 | K12: =B12+B11 -> 88770.4
A13: 📥 Empréstimo Mútuo — Adquirido (valor devido a outra unidade)
A14: 📤 Empréstimo Mútuo — Emprestado (valor a receber de outra unidade)
A15: POSIÇÃO LÍQUIDA = Saldo Atual + Get Net + Ch.Esp + C.Gar − Emp. Adquirido + Emp. Emprestado | K15: =K12+D12+F12-IF(ISNUMBER(K13),K13,0)+IF(ISNUMBER(K14),K14,0) -> 74059.23
A17: CAMPINAS
A18: Santander | B18: 22549.03 | C18: 160000 | G18: =B18+(C18+D18)+(E18+F18) -> 182549.03 | H18: -74808.45 | I18: =B18+H18 -> -52259.42 | J18: =IF(D18<0,1+IF('06_07'!D18<0,'06_07'!J18,0),0) -> 0 | K18: =I18 -> -52259.42
A19: Unicred PJ | E19: 200000 | F19: -198414.01 | G19: =B19+(C19+D19)+(E19+F19) -> 1585.99 | I19: =B19+H19 -> 0 | K19: =I19 -> 0
A20: Unicred PF | B20: 54898.3 | G20: =B20+(C20+D20)+(E20+F20) -> 54898.3 | I20: =B20+H20 -> 54898.3 | K20: =I20 -> 54898.3
A21: Bradesco | B21: 121.27 | G21: =B21+(C21+D21)+(E21+F21) -> 121.27 | I21: =B21+H21 -> 121.27 | K21: =I21 -> 121.27
A22: Get Net | B22: 100862.61 | C22: ← Saldo disponível para antecipação de recebíveis | K22: =B22 -> 100862.61
A23: SALDO DISPONÍVEL | B23: =SUM('06_07'!I18:I21) -> 2760.15 | C23: =C18+C19+C20+C21 -> 160000 | D23: =D18+D19+D20+D21 -> 0 | E23: =E18+E19+E20+E21 -> 200000 | F23: =F18+F19+F20+F21 -> -198414.01 | G23: =G18+G19+G20+G21 -> 239154.59 | H23: =H18+H19+H20+H21 -> -74808.45 | I23: =I18+I19+I20+I21 -> 2760.15 | J23: =J18 -> 0 | K23: =B23+B22 -> 103622.76
A24: 📥 Empréstimo Mútuo — Adquirido (valor devido a outra unidade)
A25: 📤 Empréstimo Mútuo — Emprestado (valor a receber de outra unidade)
A26: POSIÇÃO LÍQUIDA = Saldo Atual + Get Net + Ch.Esp + C.Gar − Emp. Adquirido + Emp. Emprestado | K26: =K23+D23+F23-IF(ISNUMBER(K24),K24,0)+IF(ISNUMBER(K25),K25,0) -> -94791.25
A28: VARGINHA
A29: Santander | B29: 56567.75 | C29: 100000 | E29: 50000 | G29: =B29+(C29+D29)+(E29+F29) -> 206567.75 | H29: -96219.41 | I29: =B29+H29 -> -39651.66 | J29: =IF(D29<0,1+IF('06_07'!D29<0,'06_07'!J29,0),0) -> 0 | K29: =I29 -> -39651.66
A30: Unicred | B30: 52.68 | C30: 50000 | G30: =B30+(C30+D30)+(E30+F30) -> 50052.68 | I30: =B30+H30 -> 52.68 | K30: =I30 -> 52.68
A31: Bradesco | B31: 22.43 | G31: =B31+(C31+D31)+(E31+F31) -> 22.43 | I31: =B31+H31 -> 22.43 | K31: =I31 -> 22.43
A32: Itaú CC | G32: =B32+(C32+D32)+(E32+F32) -> 0 | I32: =B32+H32 -> 0 | K32: =I32 -> 0
A33: Eireli | B33: 21795.96 | G33: =B33+(C33+D33)+(E33+F33) -> 21795.96 | I33: =B33+H33 -> 21795.96 | K33: =I33 -> 21795.96
A34: Get Net | B34: 290630.8 | C34: ← Saldo disponível para antecipação de recebíveis | K34: =B34 -> 290630.8
A35: SALDO DISPONÍVEL | B35: =SUM('06_07'!I29:I33) -> -17780.59 | C35: =C29+C30+C31+C32+C33 -> 150000 | D35: =D29+D30+D31+D32+D33 -> 0 | E35: =E29+E30+E31+E32+E33 -> 50000 | F35: =F29+F30+F31+F32+F33 -> 0 | G35: =G29+G30+G31+G32+G33 -> 278438.82 | H35: =H29+H30+H31+H32+H33 -> -96219.41 | I35: =I29+I30+I31+I32+I33 -> -17780.59 | J35: =J29 -> 0 | K35: =B35+B34 -> 272850.21
A36: 📥 Empréstimo Mútuo — Adquirido (valor devido a outra unidade)
A37: 📤 Empréstimo Mútuo — Emprestado (valor a receber de outra unidade)
A38: POSIÇÃO LÍQUIDA = Saldo Atual + Get Net + Ch.Esp + C.Gar − Emp. Adquirido + Emp. Emprestado | K38: =K35+D35+F35-IF(ISNUMBER(K36),K36,0)+IF(ISNUMBER(K37),K37,0) -> 272850.21
A40: ITAJUBÁ
A41: Santander | B41: 48802.53 | C41: 78000 | E41: 100000 | F41: -60000 | G41: =B41+(C41+D41)+(E41+F41) -> 166802.53 | H41: -95780.36 | I41: =B41+H41 -> -46977.83 | J41: =IF(D41<0,1+IF('06_07'!D41<0,'06_07'!J41,0),0) -> 0 | K41: =I41 -> -46977.83
A42: Itaú CC | G42: =B42+(C42+D42)+(E42+F42) -> 0 | I42: =B42+H42 -> 0 | K42: =I42 -> 0
A43: Itatesla | B43: 76.23 | G43: =B43+(C43+D43)+(E43+F43) -> 76.23 | I43: =B43+H43 -> 76.23 | K43: =I43 -> 76.23
A44: Get Net | C44: ← Saldo disponível para antecipação de recebíveis | K44: =B44 -> 0
...

Sheet 08_07
A1: GRUPO MAGNUS · PAINEL DE SALDOS BANCÁRIOS · 08/07/2026
A2: Quarta-feira • Julho/2026 • Dia útil 6 de 132 | F2: ◀ 07/07 Próximo: 09/07 ▶
A4: BANCO / CONTA | B4: SALDO ATUAL | C4: CH. ESP. LIMITE | D4: CH. ESP. USADO | E4: C. GAR. LIMITE | F4: C. GAR. USADA | G4: TOTAL DISPONÍVEL | H4: A PAGAR HOJE | I4: SALDO PÓS-PAG. | J4: DIAS CH. ESPECIAL | K4: SALDO ATUAL + GET NET
A5: ALFENAS
A6: Banco do Brasil | B6: 95.8 | C6: 50000 | G6: =B6+(C6+D6)+(E6+F6) -> 50095.8 | I6: =B6+H6 -> 95.8 | K6: =I6 -> 95.8
A7: Bradesco | B7: 43.71 | C7: 50000 | G7: =B7+(C7+D7)+(E7+F7) -> 50043.71 | I7: =B7+H7 -> 43.71 | K7: =I7 -> 43.71
A8: Santander | C8: 100000 | D8: -14711.17 | E8: 150000 | G8: =B8+(C8+D8)+(E8+F8) -> 235288.83 | H8: -159430.18 | I8: =B8+H8 -> -159430.18 | J8: =IF(D8<0,1+IF('07_07'!D8<0,'07_07'!J8,0),0) -> 6 | K8: =I8 -> -159430.18
A9: CEF | B9: 164.62 | G9: =B9+(C9+D9)+(E9+F9) -> 164.62 | I9: =B9+H9 -> 164.62 | K9: =I9 -> 164.62
A10: Unicred | B10: 51.44 | G10: =B10+(C10+D10)+(E10+F10) -> 51.44 | I10: =B10+H10 -> 51.44 | K10: =I10 -> 51.44
A11: Get Net | B11: 247845.01 | C11: ← Saldo disponível para antecipação de recebíveis | K11: =B11 -> 247845.01
A12: SALDO DISPONÍVEL | B12: =SUM('07_07'!I6:I10) -> -159074.61 | C12: =C6+C7+C8+C9+C10 -> 200000 | D12: =D6+D7+D8+D9+D10 -> -14711.17 | E12: =E6+E7+E8+E9+E10 -> 150000 | F12: =F6+F7+F8+F9+F10 -> 0 | G12: =G6+G7+G8+G9+G10 -> 335644.4 | H12: =H6+H7+H8+H9+H10 -> -159430.18 | I12: =I6+I7+I8+I9+I10 -> -159074.61 | J12: =J8 -> 6 | K12: =B12+B11 -> 88770.4
A13: 📥 Empréstimo Mútuo — Adquirido (valor devido a outra unidade)
A14: 📤 Empréstimo Mútuo — Emprestado (valor a receber de outra unidade)
A15: POSIÇÃO LÍQUIDA = Saldo Atual + Get Net + Ch.Esp + C.Gar − Emp. Adquirido + Emp. Emprestado | K15: =K12+D12+F12-IF(ISNUMBER(K13),K13,0)+IF(ISNUMBER(K14),K14,0) -> 74059.23
A17: CAMPINAS
A18: Santander | B18: 22549.03 | C18: 160000 | G18: =B18+(C18+D18)+(E18+F18) -> 182549.03 | H18: -74808.45 | I18: =B18+H18 -> -52259.42 | J18: =IF(D18<0,1+IF('07_07'!D18<0,'07_07'!J18,0),0) -> 0 | K18: =I18 -> -52259.42
A19: Unicred PJ | E19: 200000 | F19: -198414.01 | G19: =B19+(C19+D19)+(E19+F19) -> 1585.99 | I19: =B19+H19 -> 0 | K19: =I19 -> 0
A20: Unicred PF | B20: 54898.3 | G20: =B20+(C20+D20)+(E20+F20) -> 54898.3 | I20: =B20+H20 -> 54898.3 | K20: =I20 -> 54898.3
A21: Bradesco | B21: 121.27 | G21: =B21+(C21+D21)+(E21+F21) -> 121.27 | I21: =B21+H21 -> 121.27 | K21: =I21 -> 121.27
A22: Get Net | B22: 100862.61 | C22: ← Saldo disponível para antecipação de recebíveis | K22: =B22 -> 100862.61
A23: SALDO DISPONÍVEL | B23: =SUM('07_07'!I18:I21) -> 2760.15 | C23: =C18+C19+C20+C21 -> 160000 | D23: =D18+D19+D20+D21 -> 0 | E23: =E18+E19+E20+E21 -> 200000 | F23: =F18+F19+F20+F21 -> -198414.01 | G23: =G18+G19+G20+G21 -> 239154.59 | H23: =H18+H19+H20+H21 -> -74808.45 | I23: =I18+I19+I20+I21 -> 2760.15 | J23: =J18 -> 0 | K23: =B23+B22 -> 103622.76
A24: 📥 Empréstimo Mútuo — Adquirido (valor devido a outra unidade)
A25: 📤 Empréstimo Mútuo — Emprestado (valor a receber de outra unidade)
A26: POSIÇÃO LÍQUIDA = Saldo Atual + Get Net + Ch.Esp + C.Gar − Emp. Adquirido + Emp. Emprestado | K26: =K23+D23+F23-IF(ISNUMBER(K24),K24,0)+IF(ISNUMBER(K25),K25,0) -> -94791.25
A28: VARGINHA
A29: Santander | B29: 56567.75 | C29: 100000 | E29: 50000 | G29: =B29+(C29+D29)+(E29+F29) -> 206567.75 | H29: -96219.41 | I29: =B29+H29 -> -39651.66 | J29: =IF(D29<0,1+IF('07_07'!D29<0,'07_07'!J29,0),0) -> 0 | K29: =I29 -> -39651.66
A30: Unicred | B30: 52.68 | C30: 50000 | G30: =B30+(C30+D30)+(E30+F30) -> 50052.68 | I30: =B30+H30 -> 52.68 | K30: =I30 -> 52.68
A31: Bradesco | B31: 22.43 | G31: =B31+(C31+D31)+(E31+F31) -> 22.43 | I31: =B31+H31 -> 22.43 | K31: =I31 -> 22.43
A32: Itaú CC | G32: =B32+(C32+D32)+(E32+F32) -> 0 | I32: =B32+H32 -> 0 | K32: =I32 -> 0
A33: Eireli | B33: 21795.96 | G33: =B33+(C33+D33)+(E33+F33) -> 21795.96 | I33: =B33+H33 -> 21795.96 | K33: =I33 -> 21795.96
A34: Get Net | B34: 290630.8 | C34: ← Saldo disponível para antecipação de recebíveis | K34: =B34 -> 290630.8
A35: SALDO DISPONÍVEL | B35: =SUM('07_07'!I29:I33) -> -17780.59 | C35: =C29+C30+C31+C32+C33 -> 150000 | D35: =D29+D30+D31+D32+D33 -> 0 | E35: =E29+E30+E31+E32+E33 -> 50000 | F35: =F29+F30+F31+F32+F33 -> 0 | G35: =G29+G30+G31+G32+G33 -> 278438.82 | H35: =H29+H30+H31+H32+H33 -> -96219.41 | I35: =I29+I30+I31+I32+I33 -> -17780.59 | J35: =J29 -> 0 | K35: =B35+B34 -> 272850.21
A36: 📥 Empréstimo Mútuo — Adquirido (valor devido a outra unidade)
A37: 📤 Empréstimo Mútuo — Emprestado (valor a receber de outra unidade)
A38: POSIÇÃO LÍQUIDA = Saldo Atual + Get Net + Ch.Esp + C.Gar − Emp. Adquirido + Emp. Emprestado | K38: =K35+D35+F35-IF(ISNUMBER(K36),K36,0)+IF(ISNUMBER(K37),K37,0) -> 272850.21
A40: ITAJUBÁ
A41: Santander | B41: 48802.53 | C41: 78000 | E41: 100000 | F41: -60000 | G41: =B41+(C41+D41)+(E41+F41) -> 166802.53 | H41: -95780.36 | I41: =B41+H41 -> -46977.83 | J41: =IF(D41<0,1+IF('07_07'!D41<0,'07_07'!J41,0),0) -> 0 | K41: =I41 -> -46977.83
A42: Itaú CC | G42: =B42+(C42+D42)+(E42+F42) -> 0 | I42: =B42+H42 -> 0 | K42: =I42 -> 0
A43: Itatesla | B43: 76.23 | G43: =B43+(C43+D43)+(E43+F43) -> 76.23 | I43: =B43+H43 -> 76.23 | K43: =I43 -> 76.23
A44: Get Net | C44: ← Saldo disponível para antecipação de recebíveis | K44: =B44 -> 0
...

Sheet 09_07
A1: GRUPO MAGNUS · PAINEL DE SALDOS BANCÁRIOS · 09/07/2026
A2: Quinta-feira • Julho/2026 • Dia útil 7 de 132 | F2: ◀ 08/07 Próximo: 10/07 ▶
A4: BANCO / CONTA | B4: SALDO ATUAL | C4: CH. ESP. LIMITE | D4: CH. ESP. USADO | E4: C. GAR. LIMITE | F4: C. GAR. USADA | G4: TOTAL DISPONÍVEL | H4: A PAGAR HOJE | I4: SALDO PÓS-PAG. | J4: DIAS CH. ESPECIAL | K4: SALDO ATUAL + GET NET
A5: ALFENAS
A6: Banco do Brasil | B6: 95.8 | C6: 50000 | G6: =B6+(C6+D6)+(E6+F6) -> 50095.8 | I6: =B6+H6 -> 95.8 | K6: =I6 -> 95.8
A7: Bradesco | B7: 43.71 | C7: 50000 | G7: =B7+(C7+D7)+(E7+F7) -> 50043.71 | I7: =B7+H7 -> 43.71 | K7: =I7 -> 43.71
A8: Santander | C8: 100000 | D8: -14711.17 | E8: 150000 | G8: =B8+(C8+D8)+(E8+F8) -> 235288.83 | H8: -159430.18 | I8: =B8+H8 -> -159430.18 | J8: =IF(D8<0,1+IF('08_07'!D8<0,'08_07'!J8,0),0) -> 7 | K8: =I8 -> -159430.18
A9: CEF | B9: 164.62 | G9: =B9+(C9+D9)+(E9+F9) -> 164.62 | I9: =B9+H9 -> 164.62 | K9: =I9 -> 164.62
A10: Unicred | B10: 51.44 | G10: =B10+(C10+D10)+(E10+F10) -> 51.44 | I10: =B10+H10 -> 51.44 | K10: =I10 -> 51.44
A11: Get Net | B11: 247845.01 | C11: ← Saldo disponível para antecipação de recebíveis | K11: =B11 -> 247845.01
A12: SALDO DISPONÍVEL | B12: =SUM('08_07'!I6:I10) -> -159074.61 | C12: =C6+C7+C8+C9+C10 -> 200000 | D12: =D6+D7+D8+D9+D10 -> -14711.17 | E12: =E6+E7+E8+E9+E10 -> 150000 | F12: =F6+F7+F8+F9+F10 -> 0 | G12: =G6+G7+G8+G9+G10 -> 335644.4 | H12: =H6+H7+H8+H9+H10 -> -159430.18 | I12: =I6+I7+I8+I9+I10 -> -159074.61 | J12: =J8 -> 7 | K12: =B12+B11 -> 88770.4
A13: 📥 Empréstimo Mútuo — Adquirido (valor devido a outra unidade)
A14: 📤 Empréstimo Mútuo — Emprestado (valor a receber de outra unidade)
A15: POSIÇÃO LÍQUIDA = Saldo Atual + Get Net + Ch.Esp + C.Gar − Emp. Adquirido + Emp. Emprestado | K15: =K12+D12+F12-IF(ISNUMBER(K13),K13,0)+IF(ISNUMBER(K14),K14,0) -> 74059.23
A17: CAMPINAS
A18: Santander | B18: 22549.03 | C18: 160000 | G18: =B18+(C18+D18)+(E18+F18) -> 182549.03 | H18: -74808.45 | I18: =B18+H18 -> -52259.42 | J18: =IF(D18<0,1+IF('08_07'!D18<0,'08_07'!J18,0),0) -> 0 | K18: =I18 -> -52259.42
A19: Unicred PJ | E19: 200000 | F19: -198414.01 | G19: =B19+(C19+D19)+(E19+F19) -> 1585.99 | I19: =B19+H19 -> 0 | K19: =I19 -> 0
A20: Unicred PF | B20: 54898.3 | G20: =B20+(C20+D20)+(E20+F20) -> 54898.3 | I20: =B20+H20 -> 54898.3 | K20: =I20 -> 54898.3
A21: Bradesco | B21: 121.27 | G21: =B21+(C21+D21)+(E21+F21) -> 121.27 | I21: =B21+H21 -> 121.27 | K21: =I21 -> 121.27
A22: Get Net | B22: 100862.61 | C22: ← Saldo disponível para antecipação de recebíveis | K22: =B22 -> 100862.61
A23: SALDO DISPONÍVEL | B23: =SUM('08_07'!I18:I21) -> 2760.15 | C23: =C18+C19+C20+C21 -> 160000 | D23: =D18+D19+D20+D21 -> 0 | E23: =E18+E19+E20+E21 -> 200000 | F23: =F18+F19+F20+F21 -> -198414.01 | G23: =G18+G19+G20+G21 -> 239154.59 | H23: =H18+H19+H20+H21 -> -74808.45 | I23: =I18+I19+I20+I21 -> 2760.15 | J23: =J18 -> 0 | K23: =B23+B22 -> 103622.76
A24: 📥 Empréstimo Mútuo — Adquirido (valor devido a outra unidade)
A25: 📤 Empréstimo Mútuo — Emprestado (valor a receber de outra unidade)
A26: POSIÇÃO LÍQUIDA = Saldo Atual + Get Net + Ch.Esp + C.Gar − Emp. Adquirido + Emp. Emprestado | K26: =K23+D23+F23-IF(ISNUMBER(K24),K24,0)+IF(ISNUMBER(K25),K25,0) -> -94791.25
A28: VARGINHA
A29: Santander | B29: 56567.75 | C29: 100000 | E29: 50000 | G29: =B29+(C29+D29)+(E29+F29) -> 206567.75 | H29: -96219.41 | I29: =B29+H29 -> -39651.66 | J29: =IF(D29<0,1+IF('08_07'!D29<0,'08_07'!J29,0),0) -> 0 | K29: =I29 -> -39651.66
A30: Unicred | B30: 52.68 | C30: 50000 | G30: =B30+(C30+D30)+(E30+F30) -> 50052.68 | I30: =B30+H30 -> 52.68 | K30: =I30 -> 52.68
A31: Bradesco | B31: 22.43 | G31: =B31+(C31+D31)+(E31+F31) -> 22.43 | I31: =B31+H31 -> 22.43 | K31: =I31 -> 22.43
A32: Itaú CC | G32: =B32+(C32+D32)+(E32+F32) -> 0 | I32: =B32+H32 -> 0 | K32: =I32 -> 0
A33: Eireli | B33: 21795.96 | G33: =B33+(C33+D33)+(E33+F33) -> 21795.96 | I33: =B33+H33 -> 21795.96 | K33: =I33 -> 21795.96
A34: Get Net | B34: 290630.8 | C34: ← Saldo disponível para antecipação de recebíveis | K34: =B34 -> 290630.8
A35: SALDO DISPONÍVEL | B35: =SUM('08_07'!I29:I33) -> -17780.59 | C35: =C29+C30+C31+C32+C33 -> 150000 | D35: =D29+D30+D31+D32+D33 -> 0 | E35: =E29+E30+E31+E32+E33 -> 50000 | F35: =F29+F30+F31+F32+F33 -> 0 | G35: =G29+G30+G31+G32+G33 -> 278438.82 | H35: =H29+H30+H31+H32+H33 -> -96219.41 | I35: =I29+I30+I31+I32+I33 -> -17780.59 | J35: =J29 -> 0 | K35: =B35+B34 -> 272850.21
A36: 📥 Empréstimo Mútuo — Adquirido (valor devido a outra unidade)
A37: 📤 Empréstimo Mútuo — Emprestado (valor a receber de outra unidade)
A38: POSIÇÃO LÍQUIDA = Saldo Atual + Get Net + Ch.Esp + C.Gar − Emp. Adquirido + Emp. Emprestado | K38: =K35+D35+F35-IF(ISNUMBER(K36),K36,0)+IF(ISNUMBER(K37),K37,0) -> 272850.21
A40: ITAJUBÁ
A41: Santander | B41: 48802.53 | C41: 78000 | E41: 100000 | F41: -60000 | G41: =B41+(C41+D41)+(E41+F41) -> 166802.53 | H41: -95780.36 | I41: =B41+H41 -> -46977.83 | J41: =IF(D41<0,1+IF('08_07'!D41<0,'08_07'!J41,0),0) -> 0 | K41: =I41 -> -46977.83
A42: Itaú CC | G42: =B42+(C42+D42)+(E42+F42) -> 0 | I42: =B42+H42 -> 0 | K42: =I42 -> 0
A43: Itatesla | B43: 76.23 | G43: =B43+(C43+D43)+(E43+F43) -> 76.23 | I43: =B43+H43 -> 76.23 | K43: =I43 -> 76.23
A44: Get Net | C44: ← Saldo disponível para antecipação de recebíveis | K44: =B44 -> 0
...

Sheet 10_07
A1: GRUPO MAGNUS · PAINEL DE SALDOS BANCÁRIOS · 10/07/2026
A2: Sexta-feira • Julho/2026 • Dia útil 8 de 132 | F2: ◀ 09/07 Próximo: 13/07 ▶
A4: BANCO / CONTA | B4: SALDO ATUAL | C4: CH. ESP. LIMITE | D4: CH. ESP. USADO | E4: C. GAR. LIMITE | F4: C. GAR. USADA | G4: TOTAL DISPONÍVEL | H4: A PAGAR HOJE | I4: SALDO PÓS-PAG. | J4: DIAS CH. ESPECIAL | K4: SALDO ATUAL + GET NET
A5: ALFENAS
A6: Banco do Brasil | B6: 95.8 | C6: 50000 | G6: =B6+(C6+D6)+(E6+F6) -> 50095.8 | I6: =B6+H6 -> 95.8 | K6: =I6 -> 95.8
A7: Bradesco | B7: 43.71 | C7: 50000 | G7: =B7+(C7+D7)+(E7+F7) -> 50043.71 | I7: =B7+H7 -> 43.71 | K7: =I7 -> 43.71
A8: Santander | C8: 100000 | D8: -14711.17 | E8: 150000 | G8: =B8+(C8+D8)+(E8+F8) -> 235288.83 | H8: -159430.18 | I8: =B8+H8 -> -159430.18 | J8: =IF(D8<0,1+IF('09_07'!D8<0,'09_07'!J8,0),0) -> 8 | K8: =I8 -> -159430.18
A9: CEF | B9: 164.62 | G9: =B9+(C9+D9)+(E9+F9) -> 164.62 | I9: =B9+H9 -> 164.62 | K9: =I9 -> 164.62
A10: Unicred | B10: 51.44 | G10: =B10+(C10+D10)+(E10+F10) -> 51.44 | I10: =B10+H10 -> 51.44 | K10: =I10 -> 51.44
A11: Get Net | B11: 247845.01 | C11: ← Saldo disponível para antecipação de recebíveis | K11: =B11 -> 247845.01
A12: SALDO DISPONÍVEL | B12: =SUM('09_07'!I6:I10) -> -159074.61 | C12: =C6+C7+C8+C9+C10 -> 200000 | D12: =D6+D7+D8+D9+D10 -> -14711.17 | E12: =E6+E7+E8+E9+E10 -> 150000 | F12: =F6+F7+F8+F9+F10 -> 0 | G12: =G6+G7+G8+G9+G10 -> 335644.4 | H12: =H6+H7+H8+H9+H10 -> -159430.18 | I12: =I6+I7+I8+I9+I10 -> -159074.61 | J12: =J8 -> 8 | K12: =B12+B11 -> 88770.4
A13: 📥 Empréstimo Mútuo — Adquirido (valor devido a outra unidade)
A14: 📤 Empréstimo Mútuo — Emprestado (valor a receber de outra unidade)
A15: POSIÇÃO LÍQUIDA = Saldo Atual + Get Net + Ch.Esp + C.Gar − Emp. Adquirido + Emp. Emprestado | K15: =K12+D12+F12-IF(ISNUMBER(K13),K13,0)+IF(ISNUMBER(K14),K14,0) -> 74059.23
A17: CAMPINAS
A18: Santander | B18: 22549.03 | C18: 160000 | G18: =B18+(C18+D18)+(E18+F18) -> 182549.03 | H18: -74808.45 | I18: =B18+H18 -> -52259.42 | J18: =IF(D18<0,1+IF('09_07'!D18<0,'09_07'!J18,0),0) -> 0 | K18: =I18 -> -52259.42
A19: Unicred PJ | E19: 200000 | F19: -198414.01 | G19: =B19+(C19+D19)+(E19+F19) -> 1585.99 | I19: =B19+H19 -> 0 | K19: =I19 -> 0
A20: Unicred PF | B20: 54898.3 | G20: =B20+(C20+D20)+(E20+F20) -> 54898.3 | I20: =B20+H20 -> 54898.3 | K20: =I20 -> 54898.3
A21: Bradesco | B21: 121.27 | G21: =B21+(C21+D21)+(E21+F21) -> 121.27 | I21: =B21+H21 -> 121.27 | K21: =I21 -> 121.27
A22: Get Net | B22: 100862.61 | C22: ← Saldo disponível para antecipação de recebíveis | K22: =B22 -> 100862.61
A23: SALDO DISPONÍVEL | B23: =SUM('09_07'!I18:I21) -> 2760.15 | C23: =C18+C19+C20+C21 -> 160000 | D23: =D18+D19+D20+D21 -> 0 | E23: =E18+E19+E20+E21 -> 200000 | F23: =F18+F19+F20+F21 -> -198414.01 | G23: =G18+G19+G20+G21 -> 239154.59 | H23: =H18+H19+H20+H21 -> -74808.45 | I23: =I18+I19+I20+I21 -> 2760.15 | J23: =J18 -> 0 | K23: =B23+B22 -> 103622.76
A24: 📥 Empréstimo Mútuo — Adquirido (valor devido a outra unidade)
A25: 📤 Empréstimo Mútuo — Emprestado (valor a receber de outra unidade)
A26: POSIÇÃO LÍQUIDA = Saldo Atual + Get Net + Ch.Esp + C.Gar − Emp. Adquirido + Emp. Emprestado | K26: =K23+D23+F23-IF(ISNUMBER(K24),K24,0)+IF(ISNUMBER(K25),K25,0) -> -94791.25
A28: VARGINHA
A29: Santander | B29: 56567.75 | C29: 100000 | E29: 50000 | G29: =B29+(C29+D29)+(E29+F29) -> 206567.75 | H29: -96219.41 | I29: =B29+H29 -> -39651.66 | J29: =IF(D29<0,1+IF('09_07'!D29<0,'09_07'!J29,0),0) -> 0 | K29: =I29 -> -39651.66
A30: Unicred | B30: 52.68 | C30: 50000 | G30: =B30+(C30+D30)+(E30+F30) -> 50052.68 | I30: =B30+H30 -> 52.68 | K30: =I30 -> 52.68
A31: Bradesco | B31: 22.43 | G31: =B31+(C31+D31)+(E31+F31) -> 22.43 | I31: =B31+H31 -> 22.43 | K31: =I31 -> 22.43
A32: Itaú CC | G32: =B32+(C32+D32)+(E32+F32) -> 0 | I32: =B32+H32 -> 0 | K32: =I32 -> 0
A33: Eireli | B33: 21795.96 | G33: =B33+(C33+D33)+(E33+F33) -> 21795.96 | I33: =B33+H33 -> 21795.96 | K33: =I33 -> 21795.96
A34: Get Net | B34: 290630.8 | C34: ← Saldo disponível para antecipação de recebíveis | K34: =B34 -> 290630.8
A35: SALDO DISPONÍVEL | B35: =SUM('09_07'!I29:I33) -> -17780.59 | C35: =C29+C30+C31+C32+C33 -> 150000 | D35: =D29+D30+D31+D32+D33 -> 0 | E35: =E29+E30+E31+E32+E33 -> 50000 | F35: =F29+F30+F31+F32+F33 -> 0 | G35: =G29+G30+G31+G32+G33 -> 278438.82 | H35: =H29+H30+H31+H32+H33 -> -96219.41 | I35: =I29+I30+I31+I32+I33 -> -17780.59 | J35: =J29 -> 0 | K35: =B35+B34 -> 272850.21
A36: 📥 Empréstimo Mútuo — Adquirido (valor devido a outra unidade)
A37: 📤 Empréstimo Mútuo — Emprestado (valor a receber de outra unidade)
A38: POSIÇÃO LÍQUIDA = Saldo Atual + Get Net + Ch.Esp + C.Gar − Emp. Adquirido + Emp. Emprestado | K38: =K35+D35+F35-IF(ISNUMBER(K36),K36,0)+IF(ISNUMBER(K37),K37,0) -> 272850.21
A40: ITAJUBÁ
A41: Santander | B41: 48802.53 | C41: 78000 | E41: 100000 | F41: -60000 | G41: =B41+(C41+D41)+(E41+F41) -> 166802.53 | H41: -95780.36 | I41: =B41+H41 -> -46977.83 | J41: =IF(D41<0,1+IF('09_07'!D41<0,'09_07'!J41,0),0) -> 0 | K41: =I41 -> -46977.83
A42: Itaú CC | G42: =B42+(C42+D42)+(E42+F42) -> 0 | I42: =B42+H42 -> 0 | K42: =I42 -> 0
A43: Itatesla | B43: 76.23 | G43: =B43+(C43+D43)+(E43+F43) -> 76.23 | I43: =B43+H43 -> 76.23 | K43: =I43 -> 76.23
A44: Get Net | C44: ← Saldo disponível para antecipação de recebíveis | K44: =B44 -> 0
...

Sheet 13_07
A1: GRUPO MAGNUS · PAINEL DE SALDOS BANCÁRIOS · 13/07/2026
A2: Segunda-feira • Julho/2026 • Dia útil 9 de 132 | F2: ◀ 10/07 Próximo: 14/07 ▶
A4: BANCO / CONTA | B4: SALDO ATUAL | C4: CH. ESP. LIMITE | D4: CH. ESP. USADO | E4: C. GAR. LIMITE | F4: C. GAR. USADA | G4: TOTAL DISPONÍVEL | H4: A PAGAR HOJE | I4: SALDO PÓS-PAG. | J4: DIAS CH. ESPECIAL | K4: SALDO ATUAL + GET NET
A5: ALFENAS
A6: Banco do Brasil | B6: 95.8 | C6: 50000 | G6: =B6+(C6+D6)+(E6+F6) -> 50095.8 | I6: =B6+H6 -> 95.8 | K6: =I6 -> 95.8
A7: Bradesco | B7: 43.71 | C7: 50000 | G7: =B7+(C7+D7)+(E7+F7) -> 50043.71 | I7: =B7+H7 -> 43.71 | K7: =I7 -> 43.71
A8: Santander | C8: 100000 | D8: -14711.17 | E8: 150000 | G8: =B8+(C8+D8)+(E8+F8) -> 235288.83 | H8: -159430.18 | I8: =B8+H8 -> -159430.18 | J8: =IF(D8<0,1+IF('10_07'!D8<0,'10_07'!J8,0),0) -> 9 | K8: =I8 -> -159430.18
A9: CEF | B9: 164.62 | G9: =B9+(C9+D9)+(E9+F9) -> 164.62 | I9: =B9+H9 -> 164.62 | K9: =I9 -> 164.62
A10: Unicred | B10: 51.44 | G10: =B10+(C10+D10)+(E10+F10) -> 51.44 | I10: =B10+H10 -> 51.44 | K10: =I10 -> 51.44
A11: Get Net | B11: 247845.01 | C11: ← Saldo disponível para antecipação de recebíveis | K11: =B11 -> 247845.01
A12: SALDO DISPONÍVEL | B12: =SUM('10_07'!I6:I10) -> -159074.61 | C12: =C6+C7+C8+C9+C10 -> 200000 | D12: =D6+D7+D8+D9+D10 -> -14711.17 | E12: =E6+E7+E8+E9+E10 -> 150000 | F12: =F6+F7+F8+F9+F10 -> 0 | G12: =G6+G7+G8+G9+G10 -> 335644.4 | H12: =H6+H7+H8+H9+H10 -> -159430.18 | I12: =I6+I7+I8+I9+I10 -> -159074.61 | J12: =J8 -> 9 | K12: =B12+B11 -> 88770.4
A13: 📥 Empréstimo Mútuo — Adquirido (valor devido a outra unidade)
A14: 📤 Empréstimo Mútuo — Emprestado (valor a receber de outra unidade)
A15: POSIÇÃO LÍQUIDA = Saldo Atual + Get Net + Ch.Esp + C.Gar − Emp. Adquirido + Emp. Emprestado | K15: =K12+D12+F12-IF(ISNUMBER(K13),K13,0)+IF(ISNUMBER(K14),K14,0) -> 74059.23
A17: CAMPINAS
A18: Santander | B18: 22549.03 | C18: 160000 | G18: =B18+(C18+D18)+(E18+F18) -> 182549.03 | H18: -74808.45 | I18: =B18+H18 -> -52259.42 | J18: =IF(D18<0,1+IF('10_07'!D18<0,'10_07'!J18,0),0) -> 0 | K18: =I18 -> -52259.42
A19: Unicred PJ | E19: 200000 | F19: -198414.01 | G19: =B19+(C19+D19)+(E19+F19) -> 1585.99 | I19: =B19+H19 -> 0 | K19: =I19 -> 0
A20: Unicred PF | B20: 54898.3 | G20: =B20+(C20+D20)+(E20+F20) -> 54898.3 | I20: =B20+H20 -> 54898.3 | K20: =I20 -> 54898.3
A21: Bradesco | B21: 121.27 | G21: =B21+(C21+D21)+(E21+F21) -> 121.27 | I21: =B21+H21 -> 121.27 | K21: =I21 -> 121.27
A22: Get Net | B22: 100862.61 | C22: ← Saldo disponível para antecipação de recebíveis | K22: =B22 -> 100862.61
A23: SALDO DISPONÍVEL | B23: =SUM('10_07'!I18:I21) -> 2760.15 | C23: =C18+C19+C20+C21 -> 160000 | D23: =D18+D19+D20+D21 -> 0 | E23: =E18+E19+E20+E21 -> 200000 | F23: =F18+F19+F20+F21 -> -198414.01 | G23: =G18+G19+G20+G21 -> 239154.59 | H23: =H18+H19+H20+H21 -> -74808.45 | I23: =I18+I19+I20+I21 -> 2760.15 | J23: =J18 -> 0 | K23: =B23+B22 -> 103622.76
A24: 📥 Empréstimo Mútuo — Adquirido (valor devido a outra unidade)
A25: 📤 Empréstimo Mútuo — Emprestado (valor a receber de outra unidade)
A26: POSIÇÃO LÍQUIDA = Saldo Atual + Get Net + Ch.Esp + C.Gar − Emp. Adquirido + Emp. Emprestado | K26: =K23+D23+F23-IF(ISNUMBER(K24),K24,0)+IF(ISNUMBER(K25),K25,0) -> -94791.25
A28: VARGINHA
A29: Santander | B29: 56567.75 | C29: 100000 | E29: 50000 | G29: =B29+(C29+D29)+(E29+F29) -> 206567.75 | H29: -96219.41 | I29: =B29+H29 -> -39651.66 | J29: =IF(D29<0,1+IF('10_07'!D29<0,'10_07'!J29,0),0) -> 0 | K29: =I29 -> -39651.66
A30: Unicred | B30: 52.68 | C30: 50000 | G30: =B30+(C30+D30)+(E30+F30) -> 50052.68 | I30: =B30+H30 -> 52.68 | K30: =I30 -> 52.68
A31: Bradesco | B31: 22.43 | G31: =B31+(C31+D31)+(E31+F31) -> 22.43 | I31: =B31+H31 -> 22.43 | K31: =I31 -> 22.43
A32: Itaú CC | G32: =B32+(C32+D32)+(E32+F32) -> 0 | I32: =B32+H32 -> 0 | K32: =I32 -> 0
A33: Eireli | B33: 21795.96 | G33: =B33+(C33+D33)+(E33+F33) -> 21795.96 | I33: =B33+H33 -> 21795.96 | K33: =I33 -> 21795.96
A34: Get Net | B34: 290630.8 | C34: ← Saldo disponível para antecipação de recebíveis | K34: =B34 -> 290630.8
A35: SALDO DISPONÍVEL | B35: =SUM('10_07'!I29:I33) -> -17780.59 | C35: =C29+C30+C31+C32+C33 -> 150000 | D35: =D29+D30+D31+D32+D33 -> 0 | E35: =E29+E30+E31+E32+E33 -> 50000 | F35: =F29+F30+F31+F32+F33 -> 0 | G35: =G29+G30+G31+G32+G33 -> 278438.82 | H35: =H29+H30+H31+H32+H33 -> -96219.41 | I35: =I29+I30+I31+I32+I33 -> -17780.59 | J35: =J29 -> 0 | K35: =B35+B34 -> 272850.21
A36: 📥 Empréstimo Mútuo — Adquirido (valor devido a outra unidade)
A37: 📤 Empréstimo Mútuo — Emprestado (valor a receber de outra unidade)
A38: POSIÇÃO LÍQUIDA = Saldo Atual + Get Net + Ch.Esp + C.Gar − Emp. Adquirido + Emp. Emprestado | K38: =K35+D35+F35-IF(ISNUMBER(K36),K36,0)+IF(ISNUMBER(K37),K37,0) -> 272850.21
A40: ITAJUBÁ
A41: Santander | B41: 48802.53 | C41: 78000 | E41: 100000 | F41: -60000 | G41: =B41+(C41+D41)+(E41+F41) -> 166802.53 | H41: -95780.36 | I41: =B41+H41 -> -46977.83 | J41: =IF(D41<0,1+IF('10_07'!D41<0,'10_07'!J41,0),0) -> 0 | K41: =I41 -> -46977.83
A42: Itaú CC | G42: =B42+(C42+D42)+(E42+F42) -> 0 | I42: =B42+H42 -> 0 | K42: =I42 -> 0
A43: Itatesla | B43: 76.23 | G43: =B43+(C43+D43)+(E43+F43) -> 76.23 | I43: =B43+H43 -> 76.23 | K43: =I43 -> 76.23
A44: Get Net | C44: ← Saldo disponível para antecipação de recebíveis | K44: =B44 -> 0
...

Sheet 14_07
A1: GRUPO MAGNUS · PAINEL DE SALDOS BANCÁRIOS · 14/07/2026
A2: Terça-feira • Julho/2026 • Dia útil 10 de 132 | F2: ◀ 13/07 Próximo: 15/07 ▶
A4: BANCO / CONTA | B4: SALDO ATUAL | C4: CH. ESP. LIMITE | D4: CH. ESP. USADO | E4: C. GAR. LIMITE | F4: C. GAR. USADA | G4: TOTAL DISPONÍVEL | H4: A PAGAR HOJE | I4: SALDO PÓS-PAG. | J4: DIAS CH. ESPECIAL | K4: SALDO ATUAL + GET NET
A5: ALFENAS
A6: Banco do Brasil | B6: 95.8 | C6: 50000 | G6: =B6+(C6+D6)+(E6+F6) -> 50095.8 | I6: =B6+H6 -> 95.8 | K6: =I6 -> 95.8
A7: Bradesco | B7: 43.71 | C7: 50000 | G7: =B7+(C7+D7)+(E7+F7) -> 50043.71 | I7: =B7+H7 -> 43.71 | K7: =I7 -> 43.71
A8: Santander | C8: 100000 | D8: -14711.17 | E8: 150000 | G8: =B8+(C8+D8)+(E8+F8) -> 235288.83 | H8: -159430.18 | I8: =B8+H8 -> -159430.18 | J8: =IF(D8<0,1+IF('13_07'!D8<0,'13_07'!J8,0),0) -> 10 | K8: =I8 -> -159430.18
A9: CEF | B9: 164.62 | G9: =B9+(C9+D9)+(E9+F9) -> 164.62 | I9: =B9+H9 -> 164.62 | K9: =I9 -> 164.62
A10: Unicred | B10: 51.44 | G10: =B10+(C10+D10)+(E10+F10) -> 51.44 | I10: =B10+H10 -> 51.44 | K10: =I10 -> 51.44
A11: Get Net | B11: 247845.01 | C11: ← Saldo disponível para antecipação de recebíveis | K11: =B11 -> 247845.01
A12: SALDO DISPONÍVEL | B12: =SUM('13_07'!I6:I10) -> -159074.61 | C12: =C6+C7+C8+C9+C10 -> 200000 | D12: =D6+D7+D8+D9+D10 -> -14711.17 | E12: =E6+E7+E8+E9+E10 -> 150000 | F12: =F6+F7+F8+F9+F10 -> 0 | G12: =G6+G7+G8+G9+G10 -> 335644.4 | H12: =H6+H7+H8+H9+H10 -> -159430.18 | I12: =I6+I7+I8+I9+I10 -> -159074.61 | J12: =J8 -> 10 | K12: =B12+B11 -> 88770.4
A13: 📥 Empréstimo Mútuo — Adquirido (valor devido a outra unidade)
A14: 📤 Empréstimo Mútuo — Emprestado (valor a receber de outra unidade)
A15: POSIÇÃO LÍQUIDA = Saldo Atual + Get Net + Ch.Esp + C.Gar − Emp. Adquirido + Emp. Emprestado | K15: =K12+D12+F12-IF(ISNUMBER(K13),K13,0)+IF(ISNUMBER(K14),K14,0) -> 74059.23
A17: CAMPINAS
A18: Santander | B18: 22549.03 | C18: 160000 | G18: =B18+(C18+D18)+(E18+F18) -> 182549.03 | H18: -74808.45 | I18: =B18+H18 -> -52259.42 | J18: =IF(D18<0,1+IF('13_07'!D18<0,'13_07'!J18,0),0) -> 0 | K18: =I18 -> -52259.42
A19: Unicred PJ | E19: 200000 | F19: -198414.01 | G19: =B19+(C19+D19)+(E19+F19) -> 1585.99 | I19: =B19+H19 -> 0 | K19: =I19 -> 0
A20: Unicred PF | B20: 54898.3 | G20: =B20+(C20+D20)+(E20+F20) -> 54898.3 | I20: =B20+H20 -> 54898.3 | K20: =I20 -> 54898.3
A21: Bradesco | B21: 121.27 | G21: =B21+(C21+D21)+(E21+F21) -> 121.27 | I21: =B21+H21 -> 121.27 | K21: =I21 -> 121.27
A22: Get Net | B22: 100862.61 | C22: ← Saldo disponível para antecipação de recebíveis | K22: =B22 -> 100862.61
A23: SALDO DISPONÍVEL | B23: =SUM('13_07'!I18:I21) -> 2760.15 | C23: =C18+C19+C20+C21 -> 160000 | D23: =D18+D19+D20+D21 -> 0 | E23: =E18+E19+E20+E21 -> 200000 | F23: =F18+F19+F20+F21 -> -198414.01 | G23: =G18+G19+G20+G21 -> 239154.59 | H23: =H18+H19+H20+H21 -> -74808.45 | I23: =I18+I19+I20+I21 -> 2760.15 | J23: =J18 -> 0 | K23: =B23+B22 -> 103622.76
A24: 📥 Empréstimo Mútuo — Adquirido (valor devido a outra unidade)
A25: 📤 Empréstimo Mútuo — Emprestado (valor a receber de outra unidade)
A26: POSIÇÃO LÍQUIDA = Saldo Atual + Get Net + Ch.Esp + C.Gar − Emp. Adquirido + Emp. Emprestado | K26: =K23+D23+F23-IF(ISNUMBER(K24),K24,0)+IF(ISNUMBER(K25),K25,0) -> -94791.25
A28: VARGINHA
A29: Santander | B29: 56567.75 | C29: 100000 | E29: 50000 | G29: =B29+(C29+D29)+(E29+F29) -> 206567.75 | H29: -96219.41 | I29: =B29+H29 -> -39651.66 | J29: =IF(D29<0,1+IF('13_07'!D29<0,'13_07'!J29,0),0) -> 0 | K29: =I29 -> -39651.66
A30: Unicred | B30: 52.68 | C30: 50000 | G30: =B30+(C30+D30)+(E30+F30) -> 50052.68 | I30: =B30+H30 -> 52.68 | K30: =I30 -> 52.68
A31: Bradesco | B31: 22.43 | G31: =B31+(C31+D31)+(E31+F31) -> 22.43 | I31: =B31+H31 -> 22.43 | K31: =I31 -> 22.43
A32: Itaú CC | G32: =B32+(C32+D32)+(E32+F32) -> 0 | I32: =B32+H32 -> 0 | K32: =I32 -> 0
A33: Eireli | B33: 21795.96 | G33: =B33+(C33+D33)+(E33+F33) -> 21795.96 | I33: =B33+H33 -> 21795.96 | K33: =I33 -> 21795.96
A34: Get Net | B34: 290630.8 | C34: ← Saldo disponível para antecipação de recebíveis | K34: =B34 -> 290630.8
A35: SALDO DISPONÍVEL | B35: =SUM('13_07'!I29:I33) -> -17780.59 | C35: =C29+C30+C31+C32+C33 -> 150000 | D35: =D29+D30+D31+D32+D33 -> 0 | E35: =E29+E30+E31+E32+E33 -> 50000 | F35: =F29+F30+F31+F32+F33 -> 0 | G35: =G29+G30+G31+G32+G33 -> 278438.82 | H35: =H29+H30+H31+H32+H33 -> -96219.41 | I35: =I29+I30+I31+I32+I33 -> -17780.59 | J35: =J29 -> 0 | K35: =B35+B34 -> 272850.21
A36: 📥 Empréstimo Mútuo — Adquirido (valor devido a outra unidade)
A37: 📤 Empréstimo Mútuo — Emprestado (valor a receber de outra unidade)
A38: POSIÇÃO LÍQUIDA = Saldo Atual + Get Net + Ch.Esp + C.Gar − Emp. Adquirido + Emp. Emprestado | K38: =K35+D35+F35-IF(ISNUMBER(K36),K36,0)+IF(ISNUMBER(K37),K37,0) -> 272850.21
A40: ITAJUBÁ
A41: Santander | B41: 48802.53 | C41: 78000 | E41: 100000 | F41: -60000 | G41: =B41+(C41+D41)+(E41+F41) -> 166802.53 | H41: -95780.36 | I41: =B41+H41 -> -46977.83 | J41: =IF(D41<0,1+IF('13_07'!D41<0,'13_07'!J41,0),0) -> 0 | K41: =I41 -> -46977.83
A42: Itaú CC | G42: =B42+(C42+D42)+(E42+F42) -> 0 | I42: =B42+H42 -> 0 | K42: =I42 -> 0
A43: Itatesla | B43: 76.23 | G43: =B43+(C43+D43)+(E43+F43) -> 76.23 | I43: =B43+H43 -> 76.23 | K43: =I43 -> 76.23
A44: Get Net | C44: ← Saldo disponível para antecipação de recebíveis | K44: =B44 -> 0
...

Sheet 15_07
A1: GRUPO MAGNUS · PAINEL DE SALDOS BANCÁRIOS · 15/07/2026
A2: Quarta-feira • Julho/2026 • Dia útil 11 de 132 | F2: ◀ 14/07 Próximo: 16/07 ▶
A4: BANCO / CONTA | B4: SALDO ATUAL | C4: CH. ESP. LIMITE | D4: CH. ESP. USADO | E4: C. GAR. LIMITE | F4: C. GAR. USADA | G4: TOTAL DISPONÍVEL | H4: A PAGAR HOJE | I4: SALDO PÓS-PAG. | J4: DIAS CH. ESPECIAL | K4: SALDO ATUAL + GET NET
A5: ALFENAS
A6: Banco do Brasil | B6: 95.8 | C6: 50000 | G6: =B6+(C6+D6)+(E6+F6) -> 50095.8 | I6: =B6+H6 -> 95.8 | K6: =I6 -> 95.8
A7: Bradesco | B7: 43.71 | C7: 50000 | G7: =B7+(C7+D7)+(E7+F7) -> 50043.71 | I7: =B7+H7 -> 43.71 | K7: =I7 -> 43.71
A8: Santander | C8: 100000 | D8: -14711.17 | E8: 150000 | G8: =B8+(C8+D8)+(E8+F8) -> 235288.83 | H8: -159430.18 | I8: =B8+H8 -> -159430.18 | J8: =IF(D8<0,1+IF('14_07'!D8<0,'14_07'!J8,0),0) -> 11 | K8: =I8 -> -159430.18
A9: CEF | B9: 164.62 | G9: =B9+(C9+D9)+(E9+F9) -> 164.62 | I9: =B9+H9 -> 164.62 | K9: =I9 -> 164.62
A10: Unicred | B10: 51.44 | G10: =B10+(C10+D10)+(E10+F10) -> 51.44 | I10: =B10+H10 -> 51.44 | K10: =I10 -> 51.44
A11: Get Net | B11: 247845.01 | C11: ← Saldo disponível para antecipação de recebíveis | K11: =B11 -> 247845.01
A12: SALDO DISPONÍVEL | B12: =SUM('14_07'!I6:I10) -> -159074.61 | C12: =C6+C7+C8+C9+C10 -> 200000 | D12: =D6+D7+D8+D9+D10 -> -14711.17 | E12: =E6+E7+E8+E9+E10 -> 150000 | F12: =F6+F7+F8+F9+F10 -> 0 | G12: =G6+G7+G8+G9+G10 -> 335644.4 | H12: =H6+H7+H8+H9+H10 -> -159430.18 | I12: =I6+I7+I8+I9+I10 -> -159074.61 | J12: =J8 -> 11 | K12: =B12+B11 -> 88770.4
A13: 📥 Empréstimo Mútuo — Adquirido (valor devido a outra unidade)
A14: 📤 Empréstimo Mútuo — Emprestado (valor a receber de outra unidade)
A15: POSIÇÃO LÍQUIDA = Saldo Atual + Get Net + Ch.Esp + C.Gar − Emp. Adquirido + Emp. Emprestado | K15: =K12+D12+F12-IF(ISNUMBER(K13),K13,0)+IF(ISNUMBER(K14),K14,0) -> 74059.23
A17: CAMPINAS
A18: Santander | B18: 22549.03 | C18: 160000 | G18: =B18+(C18+D18)+(E18+F18) -> 182549.03 | H18: -74808.45 | I18: =B18+H18 -> -52259.42 | J18: =IF(D18<0,1+IF('14_07'!D18<0,'14_07'!J18,0),0) -> 0 | K18: =I18 -> -52259.42
A19: Unicred PJ | E19: 200000 | F19: -198414.01 | G19: =B19+(C19+D19)+(E19+F19) -> 1585.99 | I19: =B19+H19 -> 0 | K19: =I19 -> 0
A20: Unicred PF | B20: 54898.3 | G20: =B20+(C20+D20)+(E20+F20) -> 54898.3 | I20: =B20+H20 -> 54898.3 | K20: =I20 -> 54898.3
A21: Bradesco | B21: 121.27 | G21: =B21+(C21+D21)+(E21+F21) -> 121.27 | I21: =B21+H21 -> 121.27 | K21: =I21 -> 121.27
A22: Get Net | B22: 100862.61 | C22: ← Saldo disponível para antecipação de recebíveis | K22: =B22 -> 100862.61
A23: SALDO DISPONÍVEL | B23: =SUM('14_07'!I18:I21) -> 2760.15 | C23: =C18+C19+C20+C21 -> 160000 | D23: =D18+D19+D20+D21 -> 0 | E23: =E18+E19+E20+E21 -> 200000 | F23: =F18+F19+F20+F21 -> -198414.01 | G23: =G18+G19+G20+G21 -> 239154.59 | H23: =H18+H19+H20+H21 -> -74808.45 | I23: =I18+I19+I20+I21 -> 2760.15 | J23: =J18 -> 0 | K23: =B23+B22 -> 103622.76
A24: 📥 Empréstimo Mútuo — Adquirido (valor devido a outra unidade)
A25: 📤 Empréstimo Mútuo — Emprestado (valor a receber de outra unidade)
A26: POSIÇÃO LÍQUIDA = Saldo Atual + Get Net + Ch.Esp + C.Gar − Emp. Adquirido + Emp. Emprestado | K26: =K23+D23+F23-IF(ISNUMBER(K24),K24,0)+IF(ISNUMBER(K25),K25,0) -> -94791.25
A28: VARGINHA
A29: Santander | B29: 56567.75 | C29: 100000 | E29: 50000 | G29: =B29+(C29+D29)+(E29+F29) -> 206567.75 | H29: -96219.41 | I29: =B29+H29 -> -39651.66 | J29: =IF(D29<0,1+IF('14_07'!D29<0,'14_07'!J29,0),0) -> 0 | K29: =I29 -> -39651.66
A30: Unicred | B30: 52.68 | C30: 50000 | G30: =B30+(C30+D30)+(E30+F30) -> 50052.68 | I30: =B30+H30 -> 52.68 | K30: =I30 -> 52.68
A31: Bradesco | B31: 22.43 | G31: =B31+(C31+D31)+(E31+F31) -> 22.43 | I31: =B31+H31 -> 22.43 | K31: =I31 -> 22.43
A32: Itaú CC | G32: =B32+(C32+D32)+(E32+F32) -> 0 | I32: =B32+H32 -> 0 | K32: =I32 -> 0
A33: Eireli | B33: 21795.96 | G33: =B33+(C33+D33)+(E33+F33) -> 21795.96 | I33: =B33+H33 -> 21795.96 | K33: =I33 -> 21795.96
A34: Get Net | B34: 290630.8 | C34: ← Saldo disponível para antecipação de recebíveis | K34: =B34 -> 290630.8
A35: SALDO DISPONÍVEL | B35: =SUM('14_07'!I29:I33) -> -17780.59 | C35: =C29+C30+C31+C32+C33 -> 150000 | D35: =D29+D30+D31+D32+D33 -> 0 | E35: =E29+E30+E31+E32+E33 -> 50000 | F35: =F29+F30+F31+F32+F33 -> 0 | G35: =G29+G30+G31+G32+G33 -> 278438.82 | H35: =H29+H30+H31+H32+H33 -> -96219.41 | I35: =I29+I30+I31+I32+I33 -> -17780.59 | J35: =J29 -> 0 | K35: =B35+B34 -> 272850.21
A36: 📥 Empréstimo Mútuo — Adquirido (valor devido a outra unidade)
A37: 📤 Empréstimo Mútuo — Emprestado (valor a receber de outra unidade)
A38: POSIÇÃO LÍQUIDA = Saldo Atual + Get Net + Ch.Esp + C.Gar − Emp. Adquirido + Emp. Emprestado | K38: =K35+D35+F35-IF(ISNUMBER(K36),K36,0)+IF(ISNUMBER(K37),K37,0) -> 272850.21
A40: ITAJUBÁ
A41: Santander | B41: 48802.53 | C41: 78000 | E41: 100000 | F41: -60000 | G41: =B41+(C41+D41)+(E41+F41) -> 166802.53 | H41: -95780.36 | I41: =B41+H41 -> -46977.83 | J41: =IF(D41<0,1+IF('14_07'!D41<0,'14_07'!J41,0),0) -> 0 | K41: =I41 -> -46977.83
A42: Itaú CC | G42: =B42+(C42+D42)+(E42+F42) -> 0 | I42: =B42+H42 -> 0 | K42: =I42 -> 0
A43: Itatesla | B43: 76.23 | G43: =B43+(C43+D43)+(E43+F43) -> 76.23 | I43: =B43+H43 -> 76.23 | K43: =I43 -> 76.23
A44: Get Net | C44: ← Saldo disponível para antecipação de recebíveis | K44: =B44 -> 0
...

Sheet 16_07
A1: GRUPO MAGNUS · PAINEL DE SALDOS BANCÁRIOS · 16/07/2026
A2: Quinta-feira • Julho/2026 • Dia útil 12 de 132 | F2: ◀ 15/07 Próximo: 17/07 ▶
